<mujoco model="cartpole">
  <compiler angle="radian"/>
  <option timestep="0.001" gravity="0 0 -9.81" integrator="RK4"/>

  <default>
    <joint damping="0" frictionloss="0"/>

    <geom rgba="0.7 0.7 0.7 1"/>
  </default>

  <worldbody>
    <geom type="plane" size="5 5 0.1" rgba="0.93 0.93 0.93 1"/>
    <body name="cart" pos="0 0 0.03">
      <joint name="slide" type="slide" axis="1 0 0"/>
      <geom type="box" size="0.10 0.06 0.03" mass="1"/>
      <body name="pole" pos="0 0 0" euler="0 2.6179939 0">
        <joint name="hinge" type="hinge" axis="0 1 0"/>

        <geom type="capsule" fromto="0 0 0  0 0 -0.3"
              size="0.0001" density="1e-6"
              contype="2" conaffinity="2"/>

        <body name="bob" pos="0 0 -0.3">
          <geom type="sphere" size="0.0002" mass="0.2"
                rgba="0.2 0.2 0.8 1"
                contype="2" conaffinity="2"/>
        </body>
      </body>
    </body>
  </worldbody>

  <actuator>
    <motor name="u" joint="slide" gear="1.0"/>
  </actuator>
</mujoco>
