<mujoco>
  <option timestep="0.001" gravity="0 0 -9.81">
  </option>

  <asset>
    <texture type="2d" name="groundplane" builtin="checker" mark="edge" rgb1="0.2 0.3 0.4" rgb2="0.1 0.2 0.3" markrgb="0.8 0.8 0.8" width="300" height="300"/>
    <material name="groundplane" texture="groundplane" texuniform="true" texrepeat="5 5" reflectance="0.2"/>
  </asset>

  <worldbody>
    <light pos="0 0 1.5" dir="0 0 -1" directional="true"/>

    <geom name="floor"
          size="0 0 0.05"
          type="plane"
          material="groundplane"
          friction="0.5 0 0"
          condim="6"
          solref="-100000 -1000"
          priority="1"
    />

    <body name="bar">
      <joint name="slide_x" type="slide" axis="1 0 0" />
      <joint name="slide_z" type="slide" axis="0 0 1" />
      <joint name="rotate_y" type="hinge" axis="0 1 0" />

      <inertial pos="0 0 0" mass="0.5" diaginertia="1e-5 0.00166667 0.00166667" />

      <geom name="bar_upper"
            type="capsule"
            fromto="-0.1 0 0 0 0 0"
            size="0.01"
            rgba="0.8 0.2 0.2 1"
            contype="0"
            conaffinity="0" />

      <geom name="bar_lower"
            type="capsule"
            fromto="0 0 0 0.1 0 0"
            size="0.01"
            rgba="0.8 0.2 0.2 1" />
    </body>
  </worldbody>

  <keyframe>
    <key name="init"
         qpos="0 0.3 0.7854"
         qvel="0 0 0" />
  </keyframe>

</mujoco>